<?xml version="1.0"?>
<robot name="robot2">
   
    <material name="grey">
        <color rgba="0.2 0.2 0.2 1"/>
    </material>

    <material name="white">
        <color rgba="1 1 1 1"/>
    </material>

    <material name="orange">
        <color rgba="1 0.3 0.1 1"/>
    </material>

    <material name="blue">
        <color rgba="0 0 1 1"/>
    </material>

    <material name="red">
        <color rgba="1 0 0 1"/>
    </material>
   
    <link name="world"></link>

    <joint name="world_to_base" type="fixed">
        <parent link="world" />
        <child link="base_link" />
        <origin xyz="2 0 0" rpy="0 0 0"/>
    </joint>

    <link name="base_link">
        <visual>
            <origin xyz="0 0 0.1" rpy="0 0 0"/>
            <geometry>
                <box size="0.5 0.5 0.2" />
            </geometry>
            <material name="grey"/>
        </visual>
    </link>

    <joint name="first_joint" type="revolute">
        <origin xyz="0.0 0.0 0.2" rpy="0.0 0.0 0.0"/>
        <parent link="base_link"/>
        <child link="first_link"/>
        <axis xyz="1 0 0.0"/>
        <limit lower="-1.57" upper="1.57" effort="0.1" velocity="0.2"/>
    </joint>
   


    <link name="first_link">
        <visual>
            <origin xyz="0 0 0.5" rpy="0 0 0"/>
            <geometry>
                <cylinder length="1" radius="0.1" />
            </geometry>
             <material name="white"/>
        </visual>

        <collision>
            <origin xyz="0 0 0.5" rpy="0 0 0"/>
            <geometry>
                <cylinder length="1" radius="0.1" />
            </geometry>
        </collision>

        <inertial>
           <mass value="5"/>
           <origin xyz="0 0 0.5" rpy="0 0 0"/>
           <inertia ixx="0.4" ixy="0.0" ixz="0.0" iyy="0.4" iyz="0.0" izz="0.03"/>   
        </inertial>

    </link>


    <joint name="second_joint" type="revolute">
        <origin xyz="0.0 0.0 1.0" rpy="-1.57  0.0 0.0"/>
        <parent link="first_link"/>
        <child link="second_link"/>
        <axis xyz="1 0 0.0"/>
        <limit lower="-1.57" upper="1.57" effort="0.1" velocity="0.2"/>
    </joint>


    <link name="second_link">
        <visual>
            <origin xyz="0 0 0.35" rpy="0 0 0"/>
            <geometry>
                <cylinder length="0.7" radius="0.07" />
            </geometry>
             <material name="blue"/>
        </visual>

        <collision>
            <origin xyz="0 0 0.35" rpy="0 0 0"/>
            <geometry>
                <cylinder length="0.7" radius="0.07" />
            </geometry>
        </collision>

        <inertial>
           <mass value="3"/>
           <origin xyz="0 0 0.35" rpy="0 0 0"/>
           <inertia ixx="0.4" ixy="0.0" ixz="0.0" iyy="0.4" iyz="0.0" izz="0.03"/>   
        </inertial>

    </link>

    <joint name="TCP_joint" type="fixed">
        <origin xyz="0.0 0.0 0.7" rpy="0  0.0 0.0"/>
        <parent link="second_link"/>
        <child link="TCP_link"/>
    </joint>


    <link name="TCP_link">
        <visual>
            <origin xyz="0 0 0" rpy="0 0 0"/>
            <geometry>
                <sphere radius="0.07"/>
            </geometry> 
             <material name="white"/>
        </visual>

        <collision>
            <origin xyz="0 0 0" rpy="0 0 0"/>
            <geometry>
                <sphere radius="0.07"/>
            </geometry>
        </collision>

        <inertial>
           <mass value="0.5"/>
           <origin xyz="0 0 0" rpy="0 0 0"/>
           <inertia ixx="0.001" ixy="0.0" ixz="0.0" iyy="0.001" iyz="0.0" izz="0.0001"/>   
        </inertial>

    </link>

    

</robot>

    